Workbook
Name PV_Account: 'سند پرداخت وجه'!$C$8
Name PV_AmountWords: 'سند پرداخت وجه'!$C$24
Name PV_Attachments: 'سند پرداخت وجه'!$C$33
Name PV_Currency: 'سند پرداخت وجه'!$G$9
Name PV_Date: 'سند پرداخت وجه'!$E$5
Name PV_DocNo: 'سند پرداخت وجه'!$C$5
Name PV_Item_Desc: 'سند پرداخت وجه'!$B$13
Name PV_Item_Note: 'سند پرداخت وجه'!$G$13
Name PV_Item_Price: 'سند پرداخت وجه'!$E$13
Name PV_Item_Qty: 'سند پرداخت وجه'!$D$13
Name PV_PayType: 'سند پرداخت وجه'!$E$8
Name PV_Receiver: 'سند پرداخت وجه'!$C$27
Name PV_ReceiverPhone: 'سند پرداخت وجه'!$G$27
Name PV_ReceiverTazkira: 'سند پرداخت وجه'!$E$27
Name PV_Subject: 'سند پرداخت وجه'!$C$9
Name PV_Total: 'سند پرداخت وجه'!$F$23
Name PV_TransferNo: 'سند پرداخت وجه'!$G$8

Sheet فهرست و راهنما
A1: مؤسسهٔ خیریه، فرهنگی و اجتماعی منجی موعود ( عج )
A2: تحت اشراف حاج آقای مصباح موسوی، نمایندهٔ مرجع عالیقدر شیعه حضرت آیت‌الله العظمی سیستانی ( دام ظله العالی )
A3: مجموعهٔ فورم ها و اسناد اداری – مالی
A4: الف) معلومات پایهٔ مؤسسه و مرکز ( یک بار تکمیل شود – در تمام فورم ها خودکار درج می‌گردد )
A5: نام مؤسسه ( سطر اول سرصفحه ) | C5: مؤسسهٔ خیریه، فرهنگی و اجتماعی منجی موعود ( عج ) | E5: در سرصفحهٔ تمام فورم ها ظاهر می‌شود.
A6: سطر دوم سرصفحه | C6: تحت اشراف حاج آقای مصباح موسوی، نمایندهٔ مرجع عالیقدر شیعه حضرت آیت‌الله العظمی سیستانی ( دام ظله العالی ) | E6: خط دوم سرصفحه؛ در صورت نیاز خالی گذاشته شود.
A7: نام مرکز | E7: مثال: دفتر ایتام / دارالایتام هرات
A8: ولایت
A9: ولسوالی
A10: مسؤل مرکز | E10: امضاء کنندهٔ نهایی اسناد.
A11: آدرس مرکز | E11: در قراردادها و نامه ها استفاده می‌شود.
A12: شماره تماس مرکز | E12: در قراردادها و نامه ها استفاده می‌شود.
A13: سال مالی | E13: سال هجری شمسی جاری.
A15: ب) فهرست فورم ها و اسناد
A16: # | B16: عنوان سند | D16: کود فورم | E16: کاربرد | G16: امضاهای لازم
A17: 1 | B17: دفتر ثبت اسناد | D17: REG-01 | E17: ثبت و پیگیری تمام اسناد صادره و وارده | G17: مسؤل اداری
A18: 2 | B18: صورت حساب کلی | D18: FIN-02 | E18: صورت حساب دوره‌ای شهریه، حقوق و مصارف هر مرکز | G18: ترتیب کننده، مسؤل ایتام، مسؤل مرکز
A19: 3 | B19: تفکیک شهریه و هزینه ها | D19: FIN-03 | E19: تفکیک حسابات بخش شهریه از بخش حقوق و مصارف | G19: ترتیب کننده، مسؤل ایتام، مسؤل مرکز
A20: 4 | B20: حقوق | D20: FIN-04 | E20: جدول معاشات، حق‌الزحمه و حق‌الماموریت کارمندان | G20: ترتیب کننده، مسؤل ایتام
A21: 5 | B21: سند پرداخت وجه | D21: FIN-01 | E21: پرداخت نقدی / حواله بابت مصارف و خریداری | G21: ترتیب کننده، تأیید کننده، پرداخت کننده، دریافت کننده
A22: 6 | B22: درخواست رخصتی | D22: HR-01 | E22: درخواست رخصتی عادی، مریضی و اضطراری کارمندان | G22: کارمند، مسؤل مستقیم، مدیریت
A23: 7 | B23: فورم ماموریت | D23: HR-02 | E23: ثبت شروع و ختم ماموریت و تصفیهٔ حق‌الماموریت | G23: کارمند، بخش اداری، مدیریت
A24: 8 | B24: وکالت موقت | D24: ORP-01 | E24: تفویض موقت صلاحیت دریافت شهریهٔ ایتام | G24: موکل، وکیل، دو شاهد، دفتر
A25: 9 | B25: قرارداد ترانسپورت | D25: CON-01 | E25: قرارداد خدمات رانندگی و ترانسپورت | G25: راننده، مؤسسه، شاهد
A26: 10 | B26: نامه انتقالی | D26: ORP-02 | E26: معرفی و انتقال خانوادهٔ تحت پوشش به ولایت دیگر | G26: مسؤل مرکز مبدأ، مرجع مقصد
A28: ج) راهنمای رنگ ها
C29: خانهٔ ورودی | D29: توسط کارمند مربوطه تکمیل می‌گردد.
A30: نمونه | C30: خانهٔ فورمول | D30: خودکار محاسبه می‌شود – تغییر داده نشود.
A31: نمونه | C31: ارتباط با شیت دیگر | D31: از شیت «فهرست و راهنما» یا شیت دیگر خوانده می‌شود.
A32: نمونه | C32: خانهٔ کلیدی | D32: ارقام نهایی و مجموع ها.
A34: راهنمای تکمیل:
A35: ۱. خانه‌های زرد رنگ محل درج معلومات توسط کارمند مربوطه است.
A36: ۲. خانه‌های خاکستری دارای فورمول بوده و نباید تغییر داده شود؛ متن سبز رنگ از شیت «فهرست و راهنما» خوانده می‌شود.
A37: ۳. پس از تکمیل و اخذ تمامی امضاها، سند به فورمت PDF تبدیل و در «دفتر ثبت اسناد» ثبت گردد.
A38: ۴. اسناد و ضمایم مرتبط، در ادامهٔ همین سند ضمیمه گردد.
A39: ۵. جهت قفل کردن فورمول ها: Review ← Protect Sheet ( بدون رمز ) – تنها خانه‌های زرد قابل تایپ می‌ماند.
A40: ۵. برای رفتن به هر فورم، روی عنوان آبی رنگ آن در جدول فوق کلیک نمایید.

Sheet دفتر ثبت اسناد
A1: ='فهرست و راهنما'!$C$5 -> مؤسسهٔ خیریه، فرهنگی و اجتماعی منجی موعود ( عج )
A2: ='فهرست و راهنما'!$C$6 -> تحت اشراف حاج آقای مصباح موسوی، نمایندهٔ مرجع عالیقدر شیعه حضرت آیت‌الله العظمی سیستانی ( دام ظله العالی )
A3: ="دفتر ثبت اسناد – سال مالی "&'فهرست و راهنما'!$C$13 -> دفتر ثبت اسناد – سال مالی
A4: ="کود فورم: REG-01" -> کود فورم: REG-01
A6: شماره | B6: تاریخ | C6: نوع سند | D6: شماره سند | E6: موضوع / طرف مقابل | F6: مبلغ ( ؋ ) | G6: ترتیب کننده | H6: وضعیت
A7: =IF(C7="","",COUNTA($C$7:C7))
A8: =IF(C8="","",COUNTA($C$7:C8))
A9: =IF(C9="","",COUNTA($C$7:C9))
A10: =IF(C10="","",COUNTA($C$7:C10))
A11: =IF(C11="","",COUNTA($C$7:C11))
A12: =IF(C12="","",COUNTA($C$7:C12))
A13: =IF(C13="","",COUNTA($C$7:C13))
A14: =IF(C14="","",COUNTA($C$7:C14))
A15: =IF(C15="","",COUNTA($C$7:C15))
A16: =IF(C16="","",COUNTA($C$7:C16))
A17: =IF(C17="","",COUNTA($C$7:C17))
A18: =IF(C18="","",COUNTA($C$7:C18))
... A46: =IF(C46="","",COUNTA($C$7:C46))
A47: مجموع مبالغ ثبت شده | F47: =SUM(F7:F46) -> 0 | G47: ="تعداد اسناد: "&COUNTA(C7:C46) -> تعداد اسناد: 0
A49: خلاصهٔ اسناد بر اساس نوع
A50: نوع سند | D50: تعداد | E50: مجموع مبلغ ( ؋ ) | G50: فیصدی مبلغ
A51: صورت حساب کلی | D51: =COUNTIF($C$7:$C$46,$A51) -> 0 | E51: =SUMIF($C$7:$C$46,$A51,$F$7:$F$46) -> 0 | G51: =IF($F$47=0,0,E51/$F$47) -> 0
A52: جدول معاشات | D52: =COUNTIF($C$7:$C$46,$A52) -> 0 | E52: =SUMIF($C$7:$C$46,$A52,$F$7:$F$46) -> 0 | G52: =IF($F$47=0,0,E52/$F$47) -> 0
A53: سند پرداخت وجه | D53: =COUNTIF($C$7:$C$46,$A53) -> 0 | E53: =SUMIF($C$7:$C$46,$A53,$F$7:$F$46) -> 0 | G53: =IF($F$47=0,0,E53/$F$47) -> 0
A54: درخواست رخصتی | D54: =COUNTIF($C$7:$C$46,$A54) -> 0 | E54: =SUMIF($C$7:$C$46,$A54,$F$7:$F$46) -> 0 | G54: =IF($F$47=0,0,E54/$F$47) -> 0
A55: فورم ماموریت | D55: =COUNTIF($C$7:$C$46,$A55) -> 0 | E55: =SUMIF($C$7:$C$46,$A55,$F$7:$F$46) -> 0 | G55: =IF($F$47=0,0,E55/$F$47) -> 0
A56: وکالت موقت | D56: =COUNTIF($C$7:$C$46,$A56) -> 0 | E56: =SUMIF($C$7:$C$46,$A56,$F$7:$F$46) -> 0 | G56: =IF($F$47=0,0,E56/$F$47) -> 0
A57: قرارداد ترانسپورت | D57: =COUNTIF($C$7:$C$46,$A57) -> 0 | E57: =SUMIF($C$7:$C$46,$A57,$F$7:$F$46) -> 0 | G57: =IF($F$47=0,0,E57/$F$47) -> 0
A58: نامه انتقالی | D58: =COUNTIF($C$7:$C$46,$A58) -> 0 | E58: =SUMIF($C$7:$C$46,$A58,$F$7:$F$46) -> 0 | G58: =IF($F$47=0,0,E58/$F$47) -> 0
A59: سایر | D59: =COUNTIF($C$7:$C$46,$A59) -> 0 | E59: =SUMIF($C$7:$C$46,$A59,$F$7:$F$46) -> 0 | G59: =IF($F$47=0,0,E59/$F$47) -> 0
A60: مجموع | D60: =SUM(D51:D59) -> 0 | E60: =SUM(E51:E59) -> 0 | G60: =IF(ROUND(E60-F47,0)=0,"مطابقت دارد","اختلاف: "&TEXT(E60-F47,"#,##0")) -> مطابقت دارد
A62: راهنمای تکمیل:
A63: ۱. خانه‌های زرد رنگ محل درج معلومات توسط کارمند مربوطه است.
A64: ۲. خانه‌های خاکستری دارای فورمول بوده و نباید تغییر داده شود؛ متن سبز رنگ از شیت «فهرست و راهنما» خوانده می‌شود.
A65: ۳. پس از تکمیل و اخذ تمامی امضاها، سند به فورمت PDF تبدیل و در «دفتر ثبت اسناد» ثبت گردد.
A66: ۴. اسناد و ضمایم مرتبط، در ادامهٔ همین سند ضمیمه گردد.
A67: ۵. جهت قفل کردن فورمول ها: Review ← Protect Sheet ( بدون رمز ) – تنها خانه‌های زرد قابل تایپ می‌ماند.
A68: ۵. هر سند صادره باید بلافاصله در این دفتر ثبت و شمارهٔ آن در فورم مربوطه درج گردد.

Sheet صورت حساب کلی
A1: ='فهرست و راهنما'!$C$5 -> مؤسسهٔ خیریه، فرهنگی و اجتماعی منجی موعود ( عج )
A2: ='فهرست و راهنما'!$C$6 -> تحت اشراف حاج آقای مصباح موسوی، نمایندهٔ مرجع عالیقدر شیعه حضرت آیت‌الله العظمی سیستانی ( دام ظله العالی )
A3: ="صورت حساب کلی ایتام – برج "&$B$10&" سال "&$E$10 -> صورت حساب کلی ایتام – برج سال
A4: ="کود فورم: FIN-02" -> کود فورم: FIN-02
A5: شماره سند | D5: تاریخ | F5: مرکز / ولایت | G5: =IF('فهرست و راهنما'!$C$7="","",'فهرست و راهنما'!$C$7&" – ")&'فهرست و راهنما'!$C$8&" / "&'فهرست و راهنما'!$C$9 -> /
A7: ۱) مشخصات سند
A8: نام مرکز | B8: ='فهرست و راهنما'!$C$7 -> 0 | D8: ولایت | E8: ='فهرست و راهنما'!$C$8 -> 0 | G8: ولسوالی | H8: ='فهرست و راهنما'!$C$9 -> 0
A9: مسؤل مرکز | B9: =IF('فهرست و راهنما'!$C$10="","",'فهرست و راهنما'!$C$10) | D9: تاریخ دریافت بودجه | G9: تهیه کننده
A10: ماه / برج | D10: سال | G10: تعداد ماه شهریه | H10: =COUNT($D$26:$D$31) -> 0
A11: تاریخ پرداخت از | D11: الی | G11: عنوان پرداختی شهریه
A13: ۲) خلاصهٔ مالی سند ( مجموع شهریه + حقوق و مصارف )
A14: شــرح | C14: مبلغ دالری ( $ ) | E14: نرخ دالر | F14: مبلغ افغانی ( ؋ ) | H14: ملاحظات
A15: مبلغ دریافتی | C15: ='تفکیک شهریه و هزینه ها'!C32 -> 0 | E15: ='تفکیک شهریه و هزینه ها'!E32 -> 0 | F15: ='تفکیک شهریه و هزینه ها'!F32 -> 0 | H15: دریافتی مجموع دو بخش
A16: باقی مانده از قبل | C16: — | E16: — | F16: ='تفکیک شهریه و هزینه ها'!F33 -> 0 | H16: انتقالی از دورهٔ قبل
A17: طلب از قبل | C17: — | E17: — | F17: ='تفکیک شهریه و هزینه ها'!F34 -> 0 | H17: کسر انتقالی از دورهٔ قبل
A18: جمع کل موجودی | C18: — | E18: — | F18: ='تفکیک شهریه و هزینه ها'!F35 -> 0 | H18: دریافتی + باقی مانده − طلب
A19: مجموع پرداختی و مصارف | C19: — | E19: — | F19: =E45 -> 0 | H19: از جدول کلی هزینه ها
A20: طلب برج فعلی | C20: — | E20: — | F20: ='تفکیک شهریه و هزینه ها'!F37 -> 0 | H20: کسری قابل انتقال به دورهٔ بعد
A21: باقی مانده برج فعلی | C21: — | E21: — | F21: ='تفکیک شهریه و هزینه ها'!F38 -> 0 | H21: مانده قابل انتقال به دورهٔ بعد
A23: ۳) تفکیک ماهانهٔ شهریه
A25: شماره | B25: ماه | D25: سال | E25: مبلغ دریافتی ( ؋ ) | G25: مبلغ پرداختی ( ؋ ) | I25: تفاوت
A26: 1 | I26: =IF(AND(E26="",G26=""),"",E26-G26)
A27: 2 | I27: =IF(AND(E27="",G27=""),"",E27-G27)
A28: 3 | I28: =IF(AND(E28="",G28=""),"",E28-G28)
A29: 4 | I29: =IF(AND(E29="",G29=""),"",E29-G29)
A30: 5 | I30: =IF(AND(E30="",G30=""),"",E30-G30)
A31: 6 | I31: =IF(AND(E31="",G31=""),"",E31-G31)
A32: جمع | E32: =SUM(E26:E31) -> 0 | G32: =SUM(G26:G31) -> 0 | I32: =E32-G32 -> 0
A34: ۴) جدول کلی هزینه ها
A35: شماره | B35: عنوان | D35: ولایت / ولسوالی | E35: مبلغ ( ؋ ) | G35: فیصدی | H35: توضیحات
A36: 1 | B36: شهریه | D36: =$E$8 -> 0 | E36: =G32 -> 0 | G36: =IF($E$45=0,0,E36/$E$45) -> 0 | H36: ="شهریهٔ برج "&$B$10&" سال "&$E$10 -> شهریهٔ برج سال
A37: 2 | B37: حقوق پرسنل | D37: =$E$8 -> 0 | E37: =حقوق!$F$33 -> 0 | G37: =IF($E$45=0,0,E37/$E$45) -> 0 | H37: ="مجموع جدول معاشات برج "&$B$10 -> مجموع جدول معاشات برج
A38: 3 | B38: ترانسپورت | D38: =$E$8 -> 0 | G38: =IF($E$45=0,0,E38/$E$45) -> 0
A39: 4 | B39: لوازم و تجهیزات | D39: =$E$8 -> 0 | G39: =IF($E$45=0,0,E39/$E$45) -> 0
A40: 5 | B40: هزینه های جاری | D40: =$E$8 -> 0 | G40: =IF($E$45=0,0,E40/$E$45) -> 0
A41: 6 | B41: کرایه ساختمان | D41: =$E$8 -> 0 | G41: =IF($E$45=0,0,E41/$E$45) -> 0
A42: 7 | B42: هزینه های متفرقه | D42: =$E$8 -> 0 | G42: =IF($E$45=0,0,E42/$E$45) -> 0
A43: 8 | D43: =$E$8 -> 0 | G43: =IF($E$45=0,0,E43/$E$45) -> 0
A44: 9 | D44: =$E$8 -> 0 | G44: =IF($E$45=0,0,E44/$E$45) -> 0
A45: جمع کل | E45: =SUM(E36:E44) -> 0 | G45: =IF($E$45=0,0,1) -> 0
...

Sheet تفکیک شهریه و هزینه ها
A1: ='فهرست و راهنما'!$C$5 -> مؤسسهٔ خیریه، فرهنگی و اجتماعی منجی موعود ( عج )
A2: ='فهرست و راهنما'!$C$6 -> تحت اشراف حاج آقای مصباح موسوی، نمایندهٔ مرجع عالیقدر شیعه حضرت آیت‌الله العظمی سیستانی ( دام ظله العالی )
A3: ="جدول تفکیک شدهٔ شهریهٔ ایتام و هزینه ها – برج "&'صورت حساب کلی'!$B$10&" سال "&'صورت حساب کلی'!$E$10 -> جدول تفکیک شدهٔ شهریهٔ ایتام و هزینه ها – برج سال
A4: ="کود فورم: FIN-03" -> کود فورم: FIN-03
A5: شماره سند | D5: تاریخ | F5: مرکز / ولایت | G5: =IF('فهرست و راهنما'!$C$7="","",'فهرست و راهنما'!$C$7&" – ")&'فهرست و راهنما'!$C$8&" / "&'فهرست و راهنما'!$C$9 -> /
A7: مشخصات سند ( خودکار )
A8: نام مرکز | B8: ='فهرست و راهنما'!$C$7 -> 0 | D8: ولایت / ولسوالی | E8: ='فهرست و راهنما'!$C$8&" / "&'فهرست و راهنما'!$C$9 -> / | G8: مسؤل مرکز | H8: =IF('فهرست و راهنما'!$C$10="","",'فهرست و راهنما'!$C$10)
A10: الف) حسابات بخش شهریه
A11: شــرح | C11: مبلغ دالری ( $ ) | E11: نرخ دالر | F11: مبلغ افغانی ( ؋ ) | H11: ملاحظات
A12: مبلغ دریافتی شهریهٔ ایتام | H12: =IF(OR(C12="",E12="",F12=""),"—",IF(ROUND(C12*E12,0)=F12,"—","تفاوت تبادله: "&TEXT(F12-ROUND(C12*E12,0),"#,##0;(#,##0)"))) -> —
A13: باقی مانده از قبل | C13: — | E13: —
A14: طلب از قبل | C14: — | E14: —
A15: جمع کل موجودی | C15: — | E15: — | F15: =F12+F13-F14 -> 0 | H15: دریافتی + باقی مانده − طلب
A16: مجموع پرداختی شهریهٔ ایتام | C16: — | E16: — | F16: ='صورت حساب کلی'!E36 -> 0
A17: طلب برج فعلی | C17: — | E17: — | F17: =MAX(0,F16-F15) -> 0 | H17: کسری قابل انتقال به دورهٔ بعد
A18: باقی مانده برج فعلی | C18: — | E18: — | F18: =MAX(0,F15-F16) -> 0 | H18: مانده قابل انتقال به دورهٔ بعد
A20: ب) حسابات بخش حقوق و هزینه ها
A21: شــرح | C21: مبلغ دالری ( $ ) | E21: نرخ دالر | F21: مبلغ افغانی ( ؋ ) | H21: ملاحظات
A22: مبلغ دریافتی حقوق و هزینه ها | H22: =IF(OR(C22="",E22="",F22=""),"—",IF(ROUND(C22*E22,0)=F22,"—","تفاوت تبادله: "&TEXT(F22-ROUND(C22*E22,0),"#,##0;(#,##0)"))) -> —
A23: باقی مانده از قبل | C23: — | E23: —
A24: طلب از قبل | C24: — | E24: —
A25: جمع کل موجودی | C25: — | E25: — | F25: =F22+F23-F24 -> 0 | H25: دریافتی + باقی مانده − طلب
A26: مجموع پرداختی حقوق و هزینه ها | C26: — | E26: — | F26: ='صورت حساب کلی'!E45-'صورت حساب کلی'!E36 -> 0
A27: طلب برج فعلی | C27: — | E27: — | F27: =MAX(0,F26-F25) -> 0 | H27: کسری قابل انتقال به دورهٔ بعد
A28: باقی مانده برج فعلی | C28: — | E28: — | F28: =MAX(0,F25-F26) -> 0 | H28: مانده قابل انتقال به دورهٔ بعد
A30: ج) مجموع شهریهٔ ایتام و هزینه ها
A31: شــرح | C31: مبلغ دالری ( $ ) | E31: نرخ دالر | F31: مبلغ افغانی ( ؋ ) | H31: ملاحظات
A32: مبلغ دریافتی | C32: =C12+C22 -> 0 | E32: =IF(C32=0,0,F32/C32) -> 0 | F32: =F12+F22 -> 0 | H32: نرخ اوسط وزنی
A33: باقی مانده از قبل | C33: — | E33: — | F33: =MAX(0,(F13+F23)-(F14+F24)) -> 0 | H33: خالص باقی مانده دو بخش
A34: طلب از قبل | C34: — | E34: — | F34: =MAX(0,(F14+F24)-(F13+F23)) -> 0 | H34: خالص طلب دو بخش
A35: جمع کل موجودی | C35: — | E35: — | F35: =F32+F33-F34 -> 0 | H35: دریافتی + باقی مانده − طلب
A36: مجموع پرداختی و مصارف | C36: — | E36: — | F36: =F16+F26 -> 0
A37: طلب برج فعلی | C37: — | E37: — | F37: =MAX(0,F36-F35) -> 0 | H37: کسری قابل انتقال به دورهٔ بعد
A38: باقی مانده برج فعلی | C38: — | E38: — | F38: =MAX(0,F35-F36) -> 0 | H38: مانده قابل انتقال به دورهٔ بعد
A40: کنترول توازن
A41: توازن بخش شهریه | D41: =IF(ROUND(F15-F16-F18+F17,0)=0,"مطابقت دارد","اختلاف: "&TEXT(F15-F16-F18+F17,"#,##0;(#,##0)")) -> مطابقت دارد | G41: موجودی − پرداختی − باقی مانده + طلب = صفر
A42: توازن بخش حقوق و هزینه ها | D42: =IF(ROUND(F25-F26-F28+F27,0)=0,"مطابقت دارد","اختلاف: "&TEXT(F25-F26-F28+F27,"#,##0;(#,##0)")) -> مطابقت دارد | G42: موجودی − پرداختی − باقی مانده + طلب = صفر
A43: توازن مجموع | D43: =IF(ROUND(F35-F36-F38+F37,0)=0,"مطابقت دارد","اختلاف: "&TEXT(F35-F36-F38+F37,"#,##0;(#,##0)")) -> مطابقت دارد | G43: موجودی − پرداختی − باقی مانده + طلب = صفر
A44: مطابقت با صورت حساب کلی | D44: =IF(ROUND(F36-'صورت حساب کلی'!E45,0)=0,"مطابقت دارد","اختلاف: "&TEXT(F36-'صورت حساب کلی'!E45,"#,##0;(#,##0)")) -> مطابقت دارد | G44: موجودی − پرداختی − باقی مانده + طلب = صفر
A46: امضاء کاربر ( تهیه کننده ) | D46: امضاء مسؤل ایتام | G46: امضاء و مهر مسؤل مرکز
...

Sheet حقوق
A1: ='فهرست و راهنما'!$C$5 -> مؤسسهٔ خیریه، فرهنگی و اجتماعی منجی موعود ( عج )
A2: ='فهرست و راهنما'!$C$6 -> تحت اشراف حاج آقای مصباح موسوی، نمایندهٔ مرجع عالیقدر شیعه حضرت آیت‌الله العظمی سیستانی ( دام ظله العالی )
A3: ="جدول معاشات کارمندان – برج "&'صورت حساب کلی'!$B$10&" سال "&'صورت حساب کلی'!$E$10 -> جدول معاشات کارمندان – برج سال
A4: ="کود فورم: FIN-04" -> کود فورم: FIN-04
A5: شماره سند | D5: تاریخ | F5: مرکز / ولایت | G5: =IF('فهرست و راهنما'!$C$7="","",'فهرست و راهنما'!$C$7&" – ")&'فهرست و راهنما'!$C$8&" / "&'فهرست و راهنما'!$C$9 -> /
A7: شماره | B7: نام و تخلص | C7: وظیفه اجرایی | D7: نوع پرداخت | E7: شرح / ملاحظات | F7: مبلغ ( ؋ ) | G7: وضعیت پرداخت | H7: محل امضاء
A8: =IF(B8="","",COUNTA($B$8:B8))
A9: =IF(B9="","",COUNTA($B$8:B9))
A10: =IF(B10="","",COUNTA($B$8:B10))
A11: =IF(B11="","",COUNTA($B$8:B11))
A12: =IF(B12="","",COUNTA($B$8:B12))
A13: =IF(B13="","",COUNTA($B$8:B13))
A14: =IF(B14="","",COUNTA($B$8:B14))
A15: =IF(B15="","",COUNTA($B$8:B15))
A16: =IF(B16="","",COUNTA($B$8:B16))
A17: =IF(B17="","",COUNTA($B$8:B17))
A18: =IF(B18="","",COUNTA($B$8:B18))
A19: =IF(B19="","",COUNTA($B$8:B19))
... A32: =IF(B32="","",COUNTA($B$8:B32))
A33: مجموع کل | F33: =SUM(F8:F32) -> 0 | G33: ="تعداد کارمند: "&COUNTA(B8:B32) -> تعداد کارمند: 0
A35: خلاصهٔ پرداخت ها بر اساس نوع ( جهت گزارش گیری )
A36: نوع پرداخت | C36: تعداد | D36: مبلغ ( ؋ )
A37: معاش | C37: =COUNTIF($D$8:$D$32,$A37) -> 0 | D37: =SUMIF($D$8:$D$32,$A37,$F$8:$F$32) -> 0
A38: حق الزحمه | C38: =COUNTIF($D$8:$D$32,$A38) -> 0 | D38: =SUMIF($D$8:$D$32,$A38,$F$8:$F$32) -> 0
A39: حق الماموریت | C39: =COUNTIF($D$8:$D$32,$A39) -> 0 | D39: =SUMIF($D$8:$D$32,$A39,$F$8:$F$32) -> 0
A40: اضافه کاری | C40: =COUNTIF($D$8:$D$32,$A40) -> 0 | D40: =SUMIF($D$8:$D$32,$A40,$F$8:$F$32) -> 0
A41: سایر | C41: =COUNTIF($D$8:$D$32,$A41) -> 0 | D41: =SUMIF($D$8:$D$32,$A41,$F$8:$F$32) -> 0
A42: مجموع | C42: =SUM(C37:C41) -> 0 | D42: =SUM(D37:D41) -> 0 | F42: =IF(ROUND(D42-F33,0)=0,"مطابقت دارد","اختلاف: "&TEXT(F33-D42,"#,##0")) -> مطابقت دارد
A44: تاریخ | C44: امضاء ترتیب کننده | F44: امضاء مسؤل ایتام
A47: راهنمای تکمیل:
A48: ۱. خانه‌های زرد رنگ محل درج معلومات توسط کارمند مربوطه است.
A49: ۲. خانه‌های خاکستری دارای فورمول بوده و نباید تغییر داده شود؛ متن سبز رنگ از شیت «فهرست و راهنما» خوانده می‌شود.
A50: ۳. پس از تکمیل و اخذ تمامی امضاها، سند به فورمت PDF تبدیل و در «دفتر ثبت اسناد» ثبت گردد.
A51: ۴. اسناد و ضمایم مرتبط، در ادامهٔ همین سند ضمیمه گردد.
A52: ۵. جهت قفل کردن فورمول ها: Review ← Protect Sheet ( بدون رمز ) – تنها خانه‌های زرد قابل تایپ می‌ماند.
A53: ۶. مجموع کل این جدول خودکار به سطر «حقوق پرسنل» در شیت «صورت حساب کلی» منتقل می‌شود.
A54: ۷. جدول خلاصه بر اساس ستون «نوع پرداخت» محاسبه می‌گردد؛ حتماً از لیست کشویی انتخاب شود.

Sheet سند پرداخت وجه
A1: ='فهرست و راهنما'!$C$5 -> مؤسسهٔ خیریه، فرهنگی و اجتماعی منجی موعود ( عج )
A2: ='فهرست و راهنما'!$C$6 -> تحت اشراف حاج آقای مصباح موسوی، نمایندهٔ مرجع عالیقدر شیعه حضرت آیت‌الله العظمی سیستانی ( دام ظله العالی )
A3: ="سند پرداخت وجه" -> سند پرداخت وجه
A4: ="کود فورم: FIN-01" -> کود فورم: FIN-01
A5: شماره سند | D5: تاریخ | F5: مرکز / ولایت | G5: =IF('فهرست و راهنما'!$C$7="","",'فهرست و راهنما'!$C$7&" – ")&'فهرست و راهنما'!$C$8&" / "&'فهرست و راهنما'!$C$9 -> /
A7: ۱) مشخصات پرداخت
A8: کود حساب / سرفصل بودجه | D8: نوع پرداخت | F8: شماره حواله
A9: بابت ( موضوع پرداخت ) | F9: ارز
A11: ۲) تفصیل اقلام
A12: شماره | B12: شرح هزینه | D12: مقدار / تعداد | E12: قیمت فی واحد | F12: مجموع | G12: ملاحظات
A13: 1 | F13: =IF(OR(D13="",E13=""),"",D13*E13)
A14: 2 | F14: =IF(OR(D14="",E14=""),"",D14*E14)
A15: 3 | F15: =IF(OR(D15="",E15=""),"",D15*E15)
A16: 4 | F16: =IF(OR(D16="",E16=""),"",D16*E16)
A17: 5 | F17: =IF(OR(D17="",E17=""),"",D17*E17)
A18: 6 | F18: =IF(OR(D18="",E18=""),"",D18*E18)
A19: 7 | F19: =IF(OR(D19="",E19=""),"",D19*E19)
A20: 8 | F20: =IF(OR(D20="",E20=""),"",D20*E20)
A21: 9 | F21: =IF(OR(D21="",E21=""),"",D21*E21)
A22: 10 | F22: =IF(OR(D22="",E22=""),"",D22*E22)
A23: جمع کل | F23: =SUM(F13:F22) -> 0 | G23: ="تعداد اقلام: "&COUNT(F13:F22) -> تعداد اقلام: 0
A24: مبلغ به حروف | C24: =داده!$F$27 -> صفر افغانی
A26: ۳) دریافت کننده
A27: نام و تخلص | D27: شماره تذکره | F27: شماره تماس
A29: ۴) تأییدات
A30: ترتیب کننده | C30: تأیید کننده ( مسؤل مرکز ) | E30: پرداخت کننده ( صندوق ) | G30: دریافت کننده ( امضاء / شصت )
A33: ضمایم ( تعداد ورق ) | D33: رسید، بل خریداری، قرارداد و سایر اسناد پشتوانه در ادامهٔ این سند ضمیمه گردد.
A35: راهنمای تکمیل:
A36: ۱. خانه‌های زرد رنگ محل درج معلومات توسط کارمند مربوطه است.
A37: ۲. خانه‌های خاکستری دارای فورمول بوده و نباید تغییر داده شود؛ متن سبز رنگ از شیت «فهرست و راهنما» خوانده می‌شود.
A38: ۳. پس از تکمیل و اخذ تمامی امضاها، سند به فورمت PDF تبدیل و در «دفتر ثبت اسناد» ثبت گردد.
A39: ۴. اسناد و ضمایم مرتبط، در ادامهٔ همین سند ضمیمه گردد.
A40: ۵. جهت قفل کردن فورمول ها: Review ← Protect Sheet ( بدون رمز ) – تنها خانه‌های زرد قابل تایپ می‌ماند.
A41: ۵. ستون «مجموع» خودکار از مقدار × قیمت فی واحد محاسبه می‌شود.
A42: ۶. «مبلغ به حروف» به‌صورت خودکار از جمع کل تولید می‌گردد.

Sheet درخواست رخصتی
A1: ='فهرست و راهنما'!$C$5 -> مؤسسهٔ خیریه، فرهنگی و اجتماعی منجی موعود ( عج )
A2: ='فهرست و راهنما'!$C$6 -> تحت اشراف حاج آقای مصباح موسوی، نمایندهٔ مرجع عالیقدر شیعه حضرت آیت‌الله العظمی سیستانی ( دام ظله العالی )
A3: ="فورم درخواست رخصتی" -> فورم درخواست رخصتی
A4: ="کود فورم: HR-01" -> کود فورم: HR-01
A5: شماره سند | D5: تاریخ | F5: مرکز / ولایت | G5: =IF('فهرست و راهنما'!$C$7="","",'فهرست و راهنما'!$C$7&" – ")&'فهرست و راهنما'!$C$8&" / "&'فهرست و راهنما'!$C$9 -> /
A7: ۱) مشخصات کارمند
A8: نام و تخلص | D8: شماره کارمند | F8: تاریخ استخدام
A9: سمت / وظیفه | D9: بخش | F9: شماره تماس
A11: ۲) نوع و مدت رخصتی
A12: نوع رخصتی | D12: از تاریخ | F12: الی تاریخ
A13: جمعاً ( روز ) | D13: تاریخ برگشت به وظیفه | F13: در صورت «سایر» توضیح دهید
A14: دلیل رخصتی
A15: آدرس و شماره تماس در مدت رخصتی
A16: جانشین در زمان غیابت | D16: امور تحویل داده شده
A18: ۳) رصید رخصتی ( توسط بخش اداری تکمیل می‌گردد )
A19: شرح | C19: تعداد روز | E19: توضیحات
A20: رخصتی مستحقهٔ سالانه | E20: مطابق پالیسی مؤسسه
A21: استفاده شده تا اکنون | E21: مجموع روزهای رخصتی استفاده شده در سال جاری
A22: باقی مانده قبل از این درخواست | C22: =C20-C21 -> 0 | E22: مستحقه − استفاده شده
A23: روزهای این درخواست | C23: =B13 -> 0 | E23: از بخش (2) خوانده می شود
A24: مانده پس از این رخصتی | C24: =C22-C23 -> 0 | E24: =IF(C24<0,"هشدار: بیش از رصید موجود درخواست شده است","باقی مانده − این درخواست") -> باقی مانده − این درخواست
A26: تعهد: متعهد می‌گردم بعد از ختم رخصتی، در تاریخ تعیین‌شده به‌موقع به وظیفه حاضر شوم و امور محوله را طبق تسلیمی به جانشین تعیین‌شده تحویل نمایم.
A28: ۴) تأییدات
A29: امضاء کارمند درخواست کننده | C29: تأیید مسؤل مستقیم | E29: تأیید بخش اداری / منابع بشری | G29: منظوری مدیریت
A32: نتیجهٔ درخواست | E32: تاریخ منظوری
A34: راهنمای تکمیل:
A35: ۱. خانه‌های زرد رنگ محل درج معلومات توسط کارمند مربوطه است.
A36: ۲. خانه‌های خاکستری دارای فورمول بوده و نباید تغییر داده شود؛ متن سبز رنگ از شیت «فهرست و راهنما» خوانده می‌شود.
A37: ۳. پس از تکمیل و اخذ تمامی امضاها، سند به فورمت PDF تبدیل و در «دفتر ثبت اسناد» ثبت گردد.
A38: ۴. اسناد و ضمایم مرتبط، در ادامهٔ همین سند ضمیمه گردد.
A39: ۵. جهت قفل کردن فورمول ها: Review ← Protect Sheet ( بدون رمز ) – تنها خانه‌های زرد قابل تایپ می‌ماند.
A40: ۵. جدول رصید رخصتی خودکار محاسبه می‌شود؛ تنها دو خانهٔ اول تکمیل گردد.
A41: ۶. یک نسخه از این فورم در دوسیهٔ شخصی کارمند و یک نسخه در دفتر حاضری نگهداری شود.

Sheet فورم ماموریت
A1: ='فهرست و راهنما'!$C$5 -> مؤسسهٔ خیریه، فرهنگی و اجتماعی منجی موعود ( عج )
A2: ='فهرست و راهنما'!$C$6 -> تحت اشراف حاج آقای مصباح موسوی، نمایندهٔ مرجع عالیقدر شیعه حضرت آیت‌الله العظمی سیستانی ( دام ظله العالی )
A3: ="فورم شروع و ختم ماموریت کارمندان" -> فورم شروع و ختم ماموریت کارمندان
A4: ="کود فورم: HR-02" -> کود فورم: HR-02
A5: شماره سند | D5: تاریخ | F5: مرکز / ولایت | G5: =IF('فهرست و راهنما'!$C$7="","",'فهرست و راهنما'!$C$7&" – ")&'فهرست و راهنما'!$C$8&" / "&'فهرست و راهنما'!$C$9 -> /
A7: ۱) مشخصات ماموریت
A8: نام و تخلص کارمند | D8: وظیفه | F8: بخش
A9: ولایت / ولسوالی محل ماموریت | D9: وسیلهٔ سفر | F9: شماره تماس در سفر
A10: هدف ماموریت
A12: ۲) شروع ماموریت
A13: اینجانب تصدیق می‌نمایم که به‌منظور انجام ماموریت فوق، از تاریخ ذیل به محل تعیین‌شده اعزام گردیدم.
A14: تاریخ شروع ماموریت | D14: ساعت حرکت | F14: امضاء کارمند
A16: ۳) ختم ماموریت و برگشت
A17: اینجانب تصدیق می‌نمایم که ماموریت محوله را به پایان رسانیده و به ادارهٔ مربوطه مراجعه نموده‌ام.
A18: تاریخ ختم ماموریت | D18: ساعت برگشت | F18: امضاء کارمند
A19: گزارش مختصر نتیجهٔ ماموریت
A21: ۴) تصفیهٔ حق‌الماموریت
A22: شرح | C22: مقدار / مبلغ | E22: توضیحات
A23: تعداد روز ماموریت | E23: مجموع روزهای حاضر در محل ماموریت
A24: حق‌الماموریت روزانه ( ؋ ) | E24: مطابق پالیسی مؤسسه
A25: مجموع حق‌الماموریت ( ؋ ) | C25: =C23*C24 -> 0 | E25: تعداد روز × حق‌الماموریت روزانه
A26: سایر مصارف قابل پرداخت ( ؋ ) | E26: کرایه، ترانسپورت و مصارف مستند
A27: پیش‌پرداخت دریافت شده ( ؋ ) | E27: مبلغ دریافت شده قبل از سفر
A28: قابل پرداخت / قابل استرداد ( ؋ ) | C28: =C25+C26-C27 -> 0 | E28: رقم مثبت: قابل پرداخت به کارمند | رقم منفی: قابل استرداد از کارمند
A30: ۵) تأییدات
A31: امضاء کارمند | C31: تأیید بخش اداری دفتر | E31: تأیید حسابداری | G31: منظوری مدیریت
A34: راهنمای تکمیل:
A35: ۱. خانه‌های زرد رنگ محل درج معلومات توسط کارمند مربوطه است.
A36: ۲. خانه‌های خاکستری دارای فورمول بوده و نباید تغییر داده شود؛ متن سبز رنگ از شیت «فهرست و راهنما» خوانده می‌شود.
A37: ۳. پس از تکمیل و اخذ تمامی امضاها، سند به فورمت PDF تبدیل و در «دفتر ثبت اسناد» ثبت گردد.
A38: ۴. اسناد و ضمایم مرتبط، در ادامهٔ همین سند ضمیمه گردد.
A39: ۵. جهت قفل کردن فورمول ها: Review ← Protect Sheet ( بدون رمز ) – تنها خانه‌های زرد قابل تایپ می‌ماند.
A40: ۵. مجموع حق‌الماموریت خودکار محاسبه شده و باید با سطر مربوطه در جدول حقوق مطابقت داشته باشد.
A41: ۶. رسیدهای مصارف در ادامهٔ این فورم ضمیمه گردد.

Sheet وکالت موقت
A1: ='فهرست و راهنما'!$C$5 -> مؤسسهٔ خیریه، فرهنگی و اجتماعی منجی موعود ( عج )
A2: ='فهرست و راهنما'!$C$6 -> تحت اشراف حاج آقای مصباح موسوی، نمایندهٔ مرجع عالیقدر شیعه حضرت آیت‌الله العظمی سیستانی ( دام ظله العالی )
A3: ="ورقهٔ وکالت موقت سرپرستی ایتام" -> ورقهٔ وکالت موقت سرپرستی ایتام
A4: ="کود فورم: ORP-01" -> کود فورم: ORP-01
A5: شماره سند | D5: تاریخ | F5: مرکز / ولایت | G5: =IF('فهرست و راهنما'!$C$7="","",'فهرست و راهنما'!$C$7&" – ")&'فهرست و راهنما'!$C$8&" / "&'فهرست و راهنما'!$C$9 -> /
A7: ۱) مشخصات وکیل‌دهنده ( سرپرست اصلی )
A8: نام و تخلص | D8: ولد ( نام پدر ) | F8: شماره تذکره
A9: کد اختصاصی / عمومی | D9: شماره تماس | F9: آدرس سکونت
A10: دلیل عدم حضور | D10: از تاریخ | F10: الی تاریخ
A12: ۲) مشخصات وکیل موقت
A13: نام و تخلص | D13: ولد ( نام پدر ) | F13: شماره تذکره
A14: نسبت با وکیل‌دهنده | D14: شماره تماس | F14: آدرس سکونت
A16: ۳) ایتام تحت پوشش این وکالت
A17: شماره | B17: نام و تخلص یتیم | D17: ولد | E17: کد یتیم | F17: سن | G17: ملاحظات
A18: 1
A19: 2
A20: 3
A21: 4
A22: 5
A23: 6
A24: تعداد ایتام تحت این وکالت | F24: =COUNTA(B18:B23) -> 0
A26: ۴) متن وکالت
A27: ="اینجانب "&B8&" فرزند "&E8&"، دارندهٔ تذکرهٔ شماره "&G8&"، به‌عنوان سرپرست قانونی ایتام با کد ( "&B9&" ) اعلام می‌دارم: به دلیل "&B10&" از تاریخ "&E10&" الی "&G10&" قادر به پیگیری مستقیم امور مربوط به دریافت شهریه نمی‌باشم. بدین وسیله آقای / خانم "&B13&" فرزند "&E13&"، دارندهٔ تذکرهٔ شماره "&G13&"، را به‌طور موقت الی تاریخ ( "&G10&" ) به‌عنوان نماینده و وکیل خود تعیین می‌نمایم تا در مدت فوق‌الذکر کلیهٔ امور مربوط به دریافت شهریهٔ ایتام تحت سرپرستی‌ام را از جانب اینجانب دریافت نماید." -> اینجانب فرزند ، دارندهٔ تذکرهٔ شماره ، به‌عنوان سرپرست قانونی ایتام با کد ( ) اعلام می‌دارم: به دلیل از تاریخ الی قادر به پیگیری مستقیم امور مربوط به دریافت شهریه نمی‌باشم. بدین وسیله آقای / خانم فرزند ، دارندهٔ تذکرهٔ شماره ، را به‌طور موقت الی تاریخ ( ) به‌عنوان نماینده و وکیل خود تعیین می‌نمایم تا در مدت فوق‌الذکر کلیهٔ امور مربوط به دریافت شهریهٔ ایتام تحت سرپرستی‌ام را از جانب اینجانب دریافت نماید.
A28: کلیهٔ مسؤولیت‌ها و تعهدات در مدت اعتبار این وکالت به عهدهٔ اینجانب ( وکیل‌دهنده ) می‌باشد. این وکالت پس از تاریخ مندرج فاقد اعتبار بوده و تمدید آن مستلزم تنظیم ورقهٔ جدید است.
A30: تاریخ تنظیم | E30: تاریخ انقضا | G30: =IF(G10="","",G10)
A32: ۵) امضاها
A33: امضاء / شصت وکیل‌دهنده | C33: امضاء / شصت وکیل موقت | E33: شاهد اول ( نام و امضاء ) | G33: شاهد دوم ( نام و امضاء )
A35: تأیید و امضاء کارمند مربوطهٔ دفتر ایتام | E35: تأیید و مهر مسؤل مرکز
A38: راهنمای تکمیل:
A39: ۱. خانه‌های زرد رنگ محل درج معلومات توسط کارمند مربوطه است.
A40: ۲. خانه‌های خاکستری دارای فورمول بوده و نباید تغییر داده شود؛ متن سبز رنگ از شیت «فهرست و راهنما» خوانده می‌شود.
A41: ۳. پس از تکمیل و اخذ تمامی امضاها، سند به فورمت PDF تبدیل و در «دفتر ثبت اسناد» ثبت گردد.
A42: ۴. اسناد و ضمایم مرتبط، در ادامهٔ همین سند ضمیمه گردد.
A43: ۵. جهت قفل کردن فورمول ها: Review ← Protect Sheet ( بدون رمز ) – تنها خانه‌های زرد قابل تایپ می‌ماند.
A44: ۵. حضور و امضای دو شاهد الزامی است.
A45: ۶. کاپی تذکرهٔ وکیل‌دهنده و وکیل موقت در ادامهٔ این ورقه ضمیمه گردد.

Sheet قرارداد ترانسپورت
A1: ='فهرست و راهنما'!$C$5 -> مؤسسهٔ خیریه، فرهنگی و اجتماعی منجی موعود ( عج )
A2: ='فهرست و راهنما'!$C$6 -> تحت اشراف حاج آقای مصباح موسوی، نمایندهٔ مرجع عالیقدر شیعه حضرت آیت‌الله العظمی سیستانی ( دام ظله العالی )
A3: ="قرارداد خدمات ترانسپورت" -> قرارداد خدمات ترانسپورت
A4: ="کود فورم: CON-01" -> کود فورم: CON-01
A5: شماره سند | D5: تاریخ | F5: مرکز / ولایت | G5: =IF('فهرست و راهنما'!$C$7="","",'فهرست و راهنما'!$C$7&" – ")&'فهرست و راهنما'!$C$8&" / "&'فهرست و راهنما'!$C$9 -> /
A7: ۱) طرفین قرارداد
A8: طرف اول ( کارفرما ) | B8: =IF('فهرست و راهنما'!$C$7="","",'فهرست و راهنما'!$C$7) | D8: نمایندهٔ کارفرما | E8: =IF('فهرست و راهنما'!$C$10="","",'فهرست و راهنما'!$C$10) | F8: شماره تماس | G8: =IF('فهرست و راهنما'!$C$12="","",'فهرست و راهنما'!$C$12)
A9: طرف دوم ( راننده ) | D9: ولد | F9: شماره تذکره
A10: شماره تماس راننده | D10: آدرس سکونت
A12: ۲) مشخصات وسیله و ساحهٔ خدمات
A13: مودل موتر | D13: شماره پلیت | F13: رنگ
A14: ساحهٔ فعالیت / مناطق
A15: نوع قرارداد | D15: از تاریخ | F15: الی تاریخ
A17: ۳) شرایط مالی
A18: شرح | C18: مبلغ / مقدار | E18: توضیحات
A19: دستمزد روزانه ( ؋ ) | E19: مطابق توافق طرفین
A20: تعداد روز کاری در ماه | E20: روزهای فعالیت مورد انتظار
A21: مجموع ماهوار ( ؋ ) | C21: =C19*C20 -> 0 | E21: دستمزد روزانه × تعداد روز کاری
A22: نرخ خدمات اضافی ( ؋ ) | E22: خارج از ساعات یا مسیرهای اضافی – طبق توافق جداگانه
A23: طرز پرداخت | E23: نقدی / حواله – ماهوار یا مطابق توافق
A25: ساعات خدمات روزانه | C25: از طلوع آفتاب الی اذان شام
A27: ۴) مسؤولیت‌ها و شرایط
A28: ۱. حفظ سلامت موتر و تجهیزات آن و ارائهٔ آن در حالت آمادهٔ کار.
A29: ۲. رعایت کامل قوانین راه، مقررات ترافیکی و اصول ایمنی.
A30: ۳. مسؤولیت خسارات وارده ناشی از بی‌احتیاطی یا تخلف راننده، بر عهدهٔ راننده می‌باشد.
A31: ۴. خدمات خارج از ساعات روزانه یا مسیرهای اضافی، طبق توافق جداگانه و با مبلغ مشخص انجام می‌شود.
A32: ۵. راننده مکلف است حضور و مسیر روزانهٔ خود را در فورم مربوطه ثبت و به تأیید مسؤل دفتر برساند.
A33: ۶. در صورت عدم رعایت شرایط این قرارداد، هر یک از طرفین حق فسخ آن را با اطلاع قبلی ( ۷ روز ) دارند.
A34: ۷. هرگونه اختلاف ناشی از این قرارداد، ابتدا از طریق مفاهمه و در صورت عدم توافق، از مجاری قانونی حل می‌گردد.
A35: ۸. این قرارداد در دو نسخهٔ واحد الاعتبار ترتیب و به هر یک از طرفین یک نسخه تسلیم گردید.
A37: ۵) امضاها
A38: امضاء / شصت راننده ( طرف دوم ) | D38: شاهد ( نام و امضاء ) | F38: امضاء و مهر نمایندهٔ مؤسسه ( طرف اول )
A41: راهنمای تکمیل:
A42: ۱. خانه‌های زرد رنگ محل درج معلومات توسط کارمند مربوطه است.
A43: ۲. خانه‌های خاکستری دارای فورمول بوده و نباید تغییر داده شود؛ متن سبز رنگ از شیت «فهرست و راهنما» خوانده می‌شود.
A44: ۳. پس از تکمیل و اخذ تمامی امضاها، سند به فورمت PDF تبدیل و در «دفتر ثبت اسناد» ثبت گردد.
A45: ۴. اسناد و ضمایم مرتبط، در ادامهٔ همین سند ضمیمه گردد.
A46: ۵. جهت قفل کردن فورمول ها: Review ← Protect Sheet ( بدون رمز ) – تنها خانه‌های زرد قابل تایپ می‌ماند.
A47: ۵. کاپی تذکره، جواز سیر و لایسنس راننده در ادامهٔ این قرارداد ضمیمه گردد.

Sheet نامه انتقالی
A1: ='فهرست و راهنما'!$C$5 -> مؤسسهٔ خیریه، فرهنگی و اجتماعی منجی موعود ( عج )
A2: ='فهرست و راهنما'!$C$6 -> تحت اشراف حاج آقای مصباح موسوی، نمایندهٔ مرجع عالیقدر شیعه حضرت آیت‌الله العظمی سیستانی ( دام ظله العالی )
A3: ="نامهٔ انتقال خانوادهٔ تحت پوشش" -> نامهٔ انتقال خانوادهٔ تحت پوشش
A4: ="کود فورم: ORP-02" -> کود فورم: ORP-02
A5: شماره سند | D5: تاریخ | F5: مرکز / ولایت | G5: =IF('فهرست و راهنما'!$C$7="","",'فهرست و راهنما'!$C$7&" – ")&'فهرست و راهنما'!$C$8&" / "&'فهرست و راهنما'!$C$9 -> /
A7: ۱) مرجع مقصد
A8: به دفتر محترم ایتام ولایت | D8: عنوانی
A10: ۲) مشخصات خانوادهٔ تحت پوشش
A11: نام و تخلص سرپرست | D11: ولد | F11: کد عمومی
A12: تعداد ایتام تحت سرپرستی | D12: ولایت مبدأ | F12: ولایت مقصد
A13: آخرین برج دریافت شهریه | D13: سال | F13: تعداد ورق ضمیمه
A14: دلیل انتقال
A16: ۳) متن نامه ( خودکار از معلومات فوق ساخته می‌شود )
A17: بسم الله الرحمن الرحیم
A18: ="به دفتر محترم ایتام ولایت "&B8&" !" -> به دفتر محترم ایتام ولایت !
A19: السلام علیکم و رحمة الله و برکاته
A20: ="محترم / محترمه ( "&B11&" ) فرزند ( "&E11&" ) دارندهٔ کد عمومی ( "&G11&" ) با تعداد ( "&B12&" ) یتیم تحت سرپرستی، که قبلاً شهریهٔ خود را از ولایت ( "&E12&" ) دریافت می‌نمودند و تا برج ( "&B13&" ) سال ( "&E13&" ) شهریه دریافت نموده‌اند، اینک این خانواده جهت انتقال به ولایت ( "&G12&" ) به ضمیمهٔ ( "&G13&" ) ورق کاپی پرونده، به آن دفتر معرفی می‌گردند. امید است در زمینه همکاری‌های لازم مبذول داشته و از نتیجه، این دفتر را اطمینان بخشید." -> محترم / محترمه ( ) فرزند ( ) دارندهٔ کد عمومی ( ) با تعداد ( ) یتیم تحت سرپرستی، که قبلاً شهریهٔ خود را از ولایت ( ) دریافت می‌نمودند و تا برج ( ) سال ( ) شهریه دریافت نموده‌اند، اینک این خانواده جهت انتقال به ولایت ( ) به ضمیمهٔ ( ) ورق کاپی پرونده، به آن دفتر معرفی می‌گردند. امید است در زمینه همکاری‌های لازم مبذول داشته و از نتیجه، این دفتر را اطمینان بخشید.
A21: با احترام
A23: ۴) ضمایم
A24: شماره | B24: شرح ضمیمه | F24: تعداد ورق | G24: ملاحظات
A25: 1
A26: 2
A27: 3
A28: 4
A29: 5
A30: مجموع اوراق ضمیمه | F30: =SUM(F25:F29) -> 0 | G30: =IF(F30=G13,"مطابقت دارد","اختلاف با متن نامه") -> مطابقت دارد
A32: ۵) امضاها
A33: امضاء و مهر مسؤل مرکز مبدأ | E33: امضاء و مهر مرجع مقصد ( رسید )
A35: تاریخ ثبت در مرجع مقصد | E35: شماره ثبت
A37: راهنمای تکمیل:
A38: ۱. خانه‌های زرد رنگ محل درج معلومات توسط کارمند مربوطه است.
A39: ۲. خانه‌های خاکستری دارای فورمول بوده و نباید تغییر داده شود؛ متن سبز رنگ از شیت «فهرست و راهنما» خوانده می‌شود.
A40: ۳. پس از تکمیل و اخذ تمامی امضاها، سند به فورمت PDF تبدیل و در «دفتر ثبت اسناد» ثبت گردد.
A41: ۴. اسناد و ضمایم مرتبط، در ادامهٔ همین سند ضمیمه گردد.
A42: ۵. جهت قفل کردن فورمول ها: Review ← Protect Sheet ( بدون رمز ) – تنها خانه‌های زرد قابل تایپ می‌ماند.
A43: ۵. متن نامه به‌صورت خودکار از بخش ۲ ساخته می‌شود؛ در متن چیزی تایپ نگردد.
A44: ۶. بخش «رسید مرجع مقصد» توسط دفتر مقصد تکمیل و یک نسخه به مرکز مبدأ اعاده گردد.

Sheet داده
A1: صفر | C1: یکصد
A2: یک | B2: بیست | C2: دوصد
A3: دو | B3: سی | C3: سه صد
A4: سه | B4: چهل | C4: چهارصد
A5: چهار | B5: پنجاه | C5: پنجصد
A6: پنج | B6: شصت | C6: ششصد
A7: شش | B7: هفتاد | C7: هفتصد
A8: هفت | B8: هشتاد | C8: هشتصد
A9: هشت | B9: نود | C9: نهصد
A10: نه
A11: ده
A12: یازده
A13: دوازده
A14: سیزده
A15: چهارده
A16: پانزده
A17: شانزده
A18: هفده
A19: هجده
A20: نزده
E21: مبلغ | H21: جدول تبدیل عدد به حروف – این شیت را حذف یا تغییر ندهید.
E22: ='سند پرداخت وجه'!F23 -> 0
E23: =INT(E22/1000000) -> 0 | F23: =IF(E23=0,"",IF(INT(E23/100)=0,"",INDEX($C$1:$C$9,INT(E23/100)))&IF(AND(INT(E23/100)>0,MOD(E23,100)>0)," و ","")&IF(MOD(E23,100)=0,"",IF(MOD(E23,100)<20,INDEX($A$1:$A$20,MOD(E23,100)+1),INDEX($B$1:$B$9,INT(MOD(E23,100)/10))&IF(MOD(E23,10)=0,""," و "&INDEX($A$1:$A$20,MOD(E23,10)+1)))))
E24: =INT(MOD(E22,1000000)/1000) -> 0 | F24: =IF(E24=0,"",IF(INT(E24/100)=0,"",INDEX($C$1:$C$9,INT(E24/100)))&IF(AND(INT(E24/100)>0,MOD(E24,100)>0)," و ","")&IF(MOD(E24,100)=0,"",IF(MOD(E24,100)<20,INDEX($A$1:$A$20,MOD(E24,100)+1),INDEX($B$1:$B$9,INT(MOD(E24,100)/10))&IF(MOD(E24,10)=0,""," و "&INDEX($A$1:$A$20,MOD(E24,10)+1)))))
E25: =MOD(E22,1000) -> 0 | F25: =IF(E25=0,"",IF(INT(E25/100)=0,"",INDEX($C$1:$C$9,INT(E25/100)))&IF(AND(INT(E25/100)>0,MOD(E25,100)>0)," و ","")&IF(MOD(E25,100)=0,"",IF(MOD(E25,100)<20,INDEX($A$1:$A$20,MOD(E25,100)+1),INDEX($B$1:$B$9,INT(MOD(E25,100)/10))&IF(MOD(E25,10)=0,""," و "&INDEX($A$1:$A$20,MOD(E25,10)+1)))))
F27: =IF(E22=0,"صفر افغانی",IF(F23="","",F23&" میلیون")&IF(AND(F23<>"",OR(F24<>"",F25<>""))," و ","")&IF(F24="","",F24&" هزار")&IF(AND(F24<>"",F25<>"")," و ","")&F25&" افغانی") -> صفر افغانی
